In function 'test':
tests/cpychecker/refcounts/PyTuple_Pack/incorrect-arg-count/input.c:30:nn: warning: mismatching argument count in call to PyTuple_Pack [enabled by default]
tests/cpychecker/refcounts/PyTuple_Pack/incorrect-arg-count/input.c:28:nn: note: graphical error report for function 'test' written out to 'tests/cpychecker/refcounts/PyTuple_Pack/incorrect-arg-count/input.c.test-refcount-errors.html'
