Trace 0:
  Transitions:
    'calling Py_FatalError() and exiting'
  Exception:
    (struct PyObject *)0 from tests/cpychecker/refcounts/Py_FatalError/correct/input.c:28
